<?xml version='1.0' encoding='UTF-8'?>
<robot name="mano">



  <link name="world"/>
  <joint name="robot_base_joint" type="fixed">
    <origin rpy="0.0 0.0 0" xyz="0 0 0"/>
    <parent link="world"/>
    <child link="link1"/>
  </joint>

	<link name="link1">
		<inertial>
			<origin rpy="0.00000 -0.00000 0.00000" xyz="0.00000 0.00000 0.00000"/>
			<mass value="0.20000"/>
			<inertia ixx="0.00024" ixy="0" ixz="0" iyy="0.00042" iyz="0" izz="0.00031"/>
		</inertial>
		<visual>
			<origin rpy="0.00000 -0.00000 0.00000" xyz="0.00000 0.00000 0.00000"/>
			<geometry>
				<mesh filename="meshes_right/0.obj" scale="1.00000 1.00000 1.00000"/>
			</geometry>
		</visual>
	</link>

	<link name="link18">
		<inertial>
			<origin rpy="0.00000 -0.00000 0.00000" xyz="0.00000 0.00000 0.00000"/>
			<mass value="0.00000"/>
			<inertia ixx="0.00000" ixy="0" ixz="0" iyy="0.00000" iyz="0" izz="0.00000"/>
		</inertial>
	</link>
	<link name="link19">
		<inertial>
			<origin rpy="0.00000 -0.00000 0.00000" xyz="0.00000 0.00000 0.00000"/>
			<mass value="0.02000"/>
			<inertia ixx="0.00001" ixy="0" ixz="0" iyy="0.00001" iyz="0" izz="0.00002"/>
		</inertial>
		<visual>
			<origin rpy="1.48103 -0.15224 1.66367" xyz="0.00000 0.00000 0.00000"/>
			<geometry>
				<mesh filename="meshes_right/13.obj" scale="1.00000 1.00000 1.00000"/>
			</geometry>
		</visual>
	</link>
	<link name="link20">
		<inertial>
			<origin rpy="0.00000 -0.00000 0.00000" xyz="0.00000 0.00000 0.00000"/>
			<mass value="0.02000"/>
			<inertia ixx="0.00001" ixy="0" ixz="0" iyy="0.00001" iyz="0" izz="0.00001"/>
		</inertial>
		<visual>
			<origin rpy="2.78364 -0.96144 -0.69747" xyz="0.00000 0.00000 0.00000"/>
			<geometry>
				<mesh filename="meshes_right/14.obj" scale="1.00000 1.00000 1.00000"/>
			</geometry>
		</visual>
	</link>
	<link name="link21">
		<inertial>
			<origin rpy="0.00000 -0.00000 0.00000" xyz="0.00000 0.00000 0.00000"/>
			<mass value="0.02000"/>
			<inertia ixx="0.00001" ixy="0" ixz="0" iyy="0.00001" iyz="0" izz="0.00001"/>
		</inertial>
		<visual>
			<origin rpy="2.78364 -0.96144 -0.69747" xyz="0.00000 0.00000 0.00000"/>
			<geometry>
				<mesh filename="meshes_right/15.obj" scale="1.00000 1.00000 1.00000"/>
			</geometry>
		</visual>
	</link>
<joint name="joint18" type="revolute">
    <limit effort="100.0" velocity="100.0" lower="-6.28" upper="6.28"/>
		<parent link="link1"/>
		<child link="link18"/>
		<dynamics damping="1.0" friction="0.0001"/>
		<origin rpy="0.72704 -1.45191 -2.45420" xyz="-0.02409 -0.01552 0.02581"/>
		<axis xyz="0.00000 1.00000 0.00000"/>
	</joint>
	<joint name="joint19" type="revolute">
      <limit effort="100.0" velocity="100.0" lower="-6.28" upper="6.28"/>

		<parent link="link18"/>
		<child link="link19"/>
		<dynamics damping="1.0" friction="0.0001"/>
		<origin rpy="0.00000 -0.00000 0.00000" xyz="0.00000 0.00000 0.00000"/>
		<axis xyz="0.00000 0.00000 1.00000"/>
	</joint>
	<joint name="joint20" type="revolute">
      <limit effort="100.0" velocity="100.0" lower="-6.28" upper="6.28"/>

		<parent link="link19"/>
		<child link="link20"/>
		<dynamics damping="1.0" friction="0.0001"/>
		<origin rpy="-1.17059 0.78985 0.99599" xyz="0.02526 -0.01760 0.00000"/>
		<axis xyz="1.00000 0.00000 0.00000"/>
	</joint>
	<joint name="joint21" type="revolute">
      <limit effort="100.0" velocity="100.0" lower="-6.28" upper="6.28"/>

		<parent link="link20"/>
		<child link="link21"/>
		<dynamics damping="1.0" friction="0.0001"/>
		<origin rpy="0.00000 -0.00000 0.00000" xyz="-0.00000 0.00000 -0.02709"/>
		<axis xyz="1.00000 0.00000 0.00000"/>
	</joint>





	<link name="link2">
		<inertial>
			<origin rpy="0.00000 -0.00000 0.00000" xyz="0.00000 0.00000 0.00000"/>
			<mass value="0.00000"/>
			<inertia ixx="0.00000" ixy="0" ixz="0" iyy="0.00000" iyz="0" izz="0.00000"/>
		</inertial>
	</link>
	<link name="link3">
		<inertial>
			<origin rpy="0.00000 -0.00000 0.00000" xyz="0.00000 0.00000 0.00000"/>
			<mass value="0.02000"/>
			<inertia ixx="0.00001" ixy="0" ixz="0" iyy="0.00000" iyz="0" izz="0.00000"/>
		</inertial>
		<visual>
			<origin rpy="1.48313 -1.51203 1.65831" xyz="0.00000 0.00000 0.00000"/>
			<geometry>
				<mesh filename="meshes_right/1.obj" scale="1.00000 1.00000 1.00000"/>
			</geometry>
		</visual>
	</link>
	<link name="link4">
		<inertial>
			<origin rpy="0.00000 -0.00000 0.00000" xyz="0.00000 0.00000 0.00000"/>
			<mass value="0.02000"/>
			<inertia ixx="0.00000" ixy="0" ixz="0" iyy="0.00000" iyz="0" izz="0.00000"/>
		</inertial>
		<visual>
			<origin rpy="1.48313 -1.51203 1.65831" xyz="0.00000 0.00000 0.00000"/>
			<geometry>
				<mesh filename="meshes_right/2.obj" scale="1.00000 1.00000 1.00000"/>
			</geometry>
		</visual>
	</link>
	<link name="link5">
		<inertial>
			<origin rpy="0.00000 -0.00000 0.00000" xyz="0.00000 0.00000 0.00000"/>
			<mass value="0.02000"/>
			<inertia ixx="0.00000" ixy="0" ixz="0" iyy="0.00000" iyz="0" izz="0.00000"/>
		</inertial>
		<visual>
			<origin rpy="1.48313 -1.51203 1.65831" xyz="0.00000 0.00000 0.00000"/>
			<geometry>
				<mesh filename="meshes_right/3.obj" scale="1.00000 1.00000 1.00000"/>
			</geometry>
		</visual>
	</link>
	<joint name="joint2" type="revolute">
      <limit effort="100.0" velocity="100.0" lower="-6.28" upper="6.28"/>

		<parent link="link1"/>
		<child link="link2"/>
		<dynamics damping="1.0" friction="0.0001"/>
		<origin rpy="0.00000 -1.56565 -3.08306" xyz="-0.08810 -0.00520 0.02069"/>
		<axis xyz="0.00000 1.00000 0.00000"/>
	</joint>
	<joint name="joint3" type="revolute">
      <limit effort="100.0" velocity="100.0" lower="-6.28" upper="6.28"/>

		<parent link="link2"/>
		<child link="link3"/>
		<dynamics damping="1.0" friction="0.0001"/>
		<origin rpy="0.00000 -0.00000 0.00000" xyz="0.00000 0.00000 0.00000"/>
		<axis xyz="1.00000 0.00000 0.00000"/>
	</joint>
	<joint name="joint4" type="revolute">
      <limit effort="100.0" velocity="100.0" lower="-6.28" upper="6.28"/>

		<parent link="link3"/>
		<child link="link4"/>
		<dynamics damping="1.0" friction="0.0001"/>
		<origin rpy="0.00000 -0.00000 0.00000" xyz="0.00238 -0.00591 -0.03238"/>
		<axis xyz="1.00000 0.00000 0.00000"/>
	</joint>
	<joint name="joint5" type="revolute">
      <limit effort="100.0" velocity="100.0" lower="-6.28" upper="6.28"/>

		<parent link="link4"/>
		<child link="link5"/>
		<dynamics damping="1.0" friction="0.0001"/>
		<origin rpy="0.00000 -0.00000 0.00000" xyz="-0.00000 0.00000 -0.02219"/>
		<axis xyz="1.00000 0.00000 0.00000"/>
	</joint>


	<link name="link6">
		<inertial>
			<origin rpy="0.00000 -0.00000 0.00000" xyz="0.00000 0.00000 0.00000"/>
			<mass value="0.00000"/>
			<inertia ixx="0.00000" ixy="0" ixz="0" iyy="0.00000" iyz="0" izz="0.00000"/>
		</inertial>
	</link>
	<link name="link7">
		<inertial>
			<origin rpy="0.00000 -0.00000 0.00000" xyz="0.00000 0.00000 0.00000"/>
			<mass value="0.02000"/>
			<inertia ixx="0.00000" ixy="0" ixz="0" iyy="0.00000" iyz="0" izz="0.00000"/>
		</inertial>
		<visual>
			<origin rpy="0.30737 -1.39204 2.81085" xyz="0.00000 0.00000 0.00000"/>
			<geometry>
				<mesh filename="meshes_right/4.obj" scale="1.00000 1.00000 1.00000"/>
			</geometry>
		</visual>
	</link>
	<link name="link8">
		<inertial>
			<origin rpy="0.00000 -0.00000 0.00000" xyz="0.00000 0.00000 0.00000"/>
			<mass value="0.02000"/>
			<inertia ixx="0.00000" ixy="0" ixz="0" iyy="0.00000" iyz="0" izz="0.00000"/>
		</inertial>
		<visual>
			<origin rpy="0.30737 -1.39204 2.81085" xyz="0.00000 0.00000 0.00000"/>
			<geometry>
				<mesh filename="meshes_right/5.obj" scale="1.00000 1.00000 1.00000"/>
			</geometry>
		</visual>
	</link>
	<link name="link9">
		<inertial>
			<origin rpy="0.00000 -0.00000 0.00000" xyz="0.00000 0.00000 0.00000"/>
			<mass value="0.02000"/>
			<inertia ixx="0.00000" ixy="0" ixz="0" iyy="0.00000" iyz="0" izz="0.00000"/>
		</inertial>
		<visual>
			<origin rpy="0.30737 -1.39204 2.81085" xyz="0.00000 0.00000 0.00000"/>
			<geometry>
				<mesh filename="meshes_right/6.obj" scale="1.00000 1.00000 1.00000"/>
			</geometry>
		</visual>
	</link>

	<joint name="joint6" type="revolute">
    <limit effort="100.0" velocity="100.0" lower="-6.28" upper="6.28"/>

		<parent link="link1"/>
		<child link="link6"/>
		<dynamics damping="1.0" friction="0.0001"/>
		<origin rpy="-0.10838 -1.39949 -2.97700" xyz="-0.09466 -0.00148 -0.00336"/>
		<axis xyz="0.00000 1.00000 0.00000"/>
	</joint>
	<joint name="joint7" type="revolute">
    <limit effort="100.0" velocity="100.0" lower="-6.28" upper="6.28"/>

		<parent link="link6"/>
		<child link="link7"/>
		<dynamics damping="1.0" friction="0.0001"/>
		<origin rpy="0.00000 -0.00000 0.00000" xyz="0.00000 0.00000 0.00000"/>
		<axis xyz="1.00000 0.00000 0.00000"/>
	</joint>
	<joint name="joint8" type="revolute">
    <limit effort="100.0" velocity="100.0" lower="-6.28" upper="6.28"/>

		<parent link="link7"/>
		<child link="link8"/>
		<dynamics damping="1.0" friction="0.0001"/>
		<origin rpy="0.00000 -0.00000 0.00000" xyz="-0.00032 -0.00356 -0.03153"/>
		<axis xyz="1.00000 0.00000 0.00000"/>
	</joint>
	<joint name="joint9" type="revolute">
    <limit effort="100.0" velocity="100.0" lower="-6.28" upper="6.28"/>

		<parent link="link8"/>
		<child link="link9"/>
		<dynamics damping="1.0" friction="0.0001"/>
		<origin rpy="0.00000 -0.00000 0.00000" xyz="0.00000 -0.00000 -0.02328"/>
		<axis xyz="1.00000 0.00000 0.00000"/>
	</joint>


	<link name="link14">
		<inertial>
			<origin rpy="0.00000 -0.00000 0.00000" xyz="0.00000 0.00000 0.00000"/>
			<mass value="0.00000"/>
			<inertia ixx="0.00000" ixy="0" ixz="0" iyy="0.00000" iyz="0" izz="0.00000"/>
		</inertial>
	</link>
	<link name="link15">
		<inertial>
			<origin rpy="0.00000 -0.00000 0.00000" xyz="0.00000 0.00000 0.00000"/>
			<mass value="0.02000"/>
			<inertia ixx="0.00000" ixy="0" ixz="0" iyy="0.00001" iyz="0" izz="0.00000"/>
		</inertial>
		<visual>
			<origin rpy="0.21763 -1.24989 3.04209" xyz="0.00000 0.00000 0.00000"/>
			<geometry>
				<mesh filename="meshes_right/10.obj" scale="1.00000 1.00000 1.00000"/>
			</geometry>
		</visual>
	</link>
	<link name="link16">
		<inertial>
			<origin rpy="0.00000 -0.00000 0.00000" xyz="0.00000 0.00000 0.00000"/>
			<mass value="0.02000"/>
			<inertia ixx="0.00001" ixy="0" ixz="0" iyy="0.00001" iyz="0" izz="0.00000"/>
		</inertial>
		<visual>
			<origin rpy="0.21763 -1.24989 3.04209" xyz="0.00000 0.00000 0.00000"/>
			<geometry>
				<mesh filename="meshes_right/11.obj" scale="1.00000 1.00000 1.00000"/>
			</geometry>
		</visual>
	</link>
	<link name="link17">
		<inertial>
			<origin rpy="0.00000 -0.00000 0.00000" xyz="0.00000 0.00000 0.00000"/>
			<mass value="0.02000"/>
			<inertia ixx="0.00000" ixy="0" ixz="0" iyy="0.00000" iyz="0" izz="0.00000"/>
		</inertial>
		<visual>
			<origin rpy="0.21763 -1.24989 3.04209" xyz="0.00000 0.00000 0.00000"/>
			<geometry>
				<mesh filename="meshes_right/12.obj" scale="1.00000 1.00000 1.00000"/>
			</geometry>
		</visual>
	</link>
	<joint name="joint14" type="revolute">
    <limit effort="100.0" velocity="100.0" lower="-6.28" upper="6.28"/>

		<parent link="link1"/>
		<child link="link14"/>
		<dynamics damping="1.0" friction="0.0001"/>
		<origin rpy="0.37943 -1.23283 2.81335" xyz="-0.08174 -0.00396 -0.02667"/>
		<axis xyz="0.00000 1.00000 0.00000"/>
	</joint>
	<joint name="joint15" type="revolute">
    <limit effort="100.0" velocity="100.0" lower="-6.28" upper="6.28"/>

		<parent link="link14"/>
		<child link="link15"/>
		<dynamics damping="1.0" friction="0.0001"/>
		<origin rpy="0.00000 -0.00000 0.00000" xyz="0.00000 0.00000 0.00000"/>
		<axis xyz="1.00000 0.00000 0.00000"/>
	</joint>
	<joint name="joint16" type="revolute">
    <limit effort="100.0" velocity="100.0" lower="-6.28" upper="6.28"/>

		<parent link="link15"/>
		<child link="link16"/>
		<dynamics damping="1.0" friction="0.0001"/>
		<origin rpy="0.00000 -0.00000 0.00000" xyz="0.00430 -0.00356 -0.02830"/>
		<axis xyz="1.00000 0.00000 0.00000"/>
	</joint>
	<joint name="joint17" type="revolute">
    <limit effort="100.0" velocity="100.0" lower="-6.28" upper="6.28"/>

		<parent link="link16"/>
		<child link="link17"/>
		<dynamics damping="1.0" friction="0.0001"/>
		<origin rpy="0.00000 -0.00000 0.00000" xyz="0.00000 0.00000 -0.02479"/>
		<axis xyz="1.00000 0.00000 0.00000"/>
	</joint>




	<link name="link10">
		<inertial>
			<origin rpy="0.00000 -0.00000 0.00000" xyz="0.00000 0.00000 0.00000"/>
			<mass value="0.00000"/>
			<inertia ixx="0.00000" ixy="0" ixz="0" iyy="0.00000" iyz="0" izz="0.00000"/>
		</inertial>
	</link>
	<link name="link11">
		<inertial>
			<origin rpy="0.00000 -0.00000 0.00000" xyz="0.00000 0.00000 0.00000"/>
			<mass value="0.02000"/>
			<inertia ixx="0.00000" ixy="0" ixz="0" iyy="0.00001" iyz="0" izz="0.00000"/>
		</inertial>
		<visual>
			<origin rpy="0.06680 -0.99258 -2.91627" xyz="0.00000 0.00000 0.00000"/>
			<geometry>
				<mesh filename="meshes_right/7.obj" scale="1.00000 1.00000 1.00000"/>
			</geometry>
		</visual>
	</link>
	<link name="link12">
		<inertial>
			<origin rpy="0.00000 -0.00000 0.00000" xyz="0.00000 0.00000 0.00000"/>
			<mass value="0.02000"/>
			<inertia ixx="0.00000" ixy="0" ixz="0" iyy="0.00001" iyz="0" izz="0.00000"/>
		</inertial>
		<visual>
			<origin rpy="0.06680 -0.99258 -2.91627" xyz="0.00000 0.00000 0.00000"/>
			<geometry>
				<mesh filename="meshes_right/8.obj" scale="1.00000 1.00000 1.00000"/>
			</geometry>
		</visual>
	</link>
	<link name="link13">
		<inertial>
			<origin rpy="0.00000 -0.00000 0.00000" xyz="0.00000 0.00000 0.00000"/>
			<mass value="0.02000"/>
			<inertia ixx="0.00000" ixy="0" ixz="0" iyy="0.00000" iyz="0" izz="0.00000"/>
		</inertial>
		<visual>
			<origin rpy="0.06680 -0.99258 -2.91627" xyz="0.00000 0.00000 0.00000"/>
			<geometry>
				<mesh filename="meshes_right/9.obj" scale="1.00000 1.00000 1.00000"/>
			</geometry>
		</visual>
	</link>
	<joint name="joint10" type="revolute">
    <limit effort="100.0" velocity="100.0" lower="-6.28" upper="6.28"/>

		<parent link="link1"/>
		<child link="link10"/>
		<dynamics damping="1.0" friction="0.0001"/>
		<origin rpy="0.43250 -0.92653 2.66149" xyz="-0.06879 -0.00994 -0.04321"/>
		<axis xyz="0.00000 1.00000 0.00000"/>
	</joint>
	<joint name="joint11" type="revolute">
    <limit effort="100.0" velocity="100.0" lower="-6.28" upper="6.28"/>

		<parent link="link10"/>
		<child link="link11"/>
		<dynamics damping="1.0" friction="0.0001"/>
		<origin rpy="0.00000 -0.00000 0.00000" xyz="0.00000 0.00000 0.00000"/>
		<axis xyz="1.00000 0.00000 0.00000"/>
	</joint>
	<joint name="joint12" type="revolute">
    <limit effort="100.0" velocity="100.0" lower="-6.28" upper="6.28"/>

		<parent link="link11"/>
		<child link="link12"/>
		<dynamics damping="1.0" friction="0.0001"/>
		<origin rpy="0.00000 -0.00000 0.00000" xyz="-0.00091 -0.00113 -0.02106"/>
		<axis xyz="1.00000 0.00000 0.00000"/>
	</joint>
	<joint name="joint13" type="revolute">
    <limit effort="100.0" velocity="100.0" lower="-6.28" upper="6.28"/>

		<parent link="link12"/>
		<child link="link13"/>
		<dynamics damping="1.0" friction="0.0001"/>
		<origin rpy="0.00000 -0.00000 0.00000" xyz="-0.00000 0.00000 -0.01895"/>
		<axis xyz="1.00000 0.00000 0.00000"/>
	</joint>  
	
</robot>
